<?xml version="1.0"?>
<robot xmlns:xacro="http://www.ros.org/xacro">
    <!-- ************************ Create wheels ************************ -->
    <xacro:macro name = "wheelz" params = "name parent mass radius leng origin_xyz">
        <link name="${name}_wheel">
            <inertial>
                <origin xyz = "0 0 0" rpy="0 1.5707 1.5707" />
                <mass value="${mass}"/>
<!--                <inertia ixx="${mass * (3*radius*radius+(leng*leng))/12}" ixy="0" ixz="0"-->
<!--                         iyy = "${mass * (3*radius*radius+(leng*leng))/12}" iyz="0" -->
<!--                         izz = "${mass * (radius*radius)/2}" />-->
                <inertia ixx = "1e-3"    ixy="0" ixz="0"
                         iyy = "1e-3"   iyz="0"
                         izz = "1e-3" />
            </inertial>

            <visual>
                <origin xyz="0 0 0" rpy="0 1.5707 1.5707" />
                <geometry>
                    <cylinder length="${leng}" radius="${radius}"/>
                </geometry>
                <material name="Black"/>
            </visual>

            <collision>
                <origin xyz = "0 0 0" rpy="0 1.5707 1.5707" />
                <geometry>
                    <cylinder length="${leng}" radius="${radius}"/>
                </geometry>
                
                <surface>
                    <friction>
                        <kp>1000000.0</kp> <!-- kp and kd for rubber -->
                        <kd>100.0</kd>
                        <mu1>1.0</mu1>      <!-- Coulomb friction mus-->
                        <mu2>1.0</mu2>      <!-- Friction coefficient muk-->
                        <fdir1>1 0 0</fdir1>
                        <slip1>0.5</slip1>
                        <slip2>0.0</slip2>
<!--                        <maxVel>1.0</maxVel>-->
<!--                        <minDepth>0.001</minDepth>-->
                    </friction>
                </surface>
            </collision>
        </link>

        <joint name="${name}_wheel_joint" type="continuous">
            <origin xyz="${origin_xyz}" rpy="0 0 0" />
            <child link="${name}_wheel"/>
            <parent link="${parent}"/>
            <axis xyz="0 1 0" rpy="0 0 0"/>
            <anchor xyz="0 0 0"/>
            <limit effort="10000" velocity="1000"/>
            <joint_properties damping="1.0" friction="1.0"/>
        </joint>
    </xacro:macro>

    <!-- ************************ Create MaxBotix Sonar EZ4 ************************ -->
    <xacro:macro name="sonar_sensor" params="name parent *origin ros_topic update_rate min_range max_range field_of_view ray_count">
        <link name="${name}_link">
            <inertial>
                <mass value="0.001" />
                <origin xyz="0 0 0" rpy="0 0 0" />
                <inertia ixx="0.000000017" ixy="0" ixz="0" iyy="0.000000017" iyz="0" izz="0.000000017" />
            </inertial>
            <visual>
                <origin xyz="0 0 0" rpy="0 0 0" />
                <geometry>
                    <mesh filename="package://tec_proyect/meshes/max_sonar_ez4.dae"/>
                </geometry>
            </visual>

            <collision>
                <origin xyz="0 0 0" rpy="0 0 0" />
                <geometry>
                    <box size="0.01 0.01 0.01" />
                </geometry>
            </collision>
        </link>

        <joint name="${name}_sonar_joint" type="fixed">
            <xacro:insert_block name="origin" />
            <child link="${name}_link"/>
            <parent link="${parent}"/>
        </joint>

        <gazebo reference="${name}_link">
          <sensor type="ray" name="${name}">
            <always_on>true</always_on>
            <update_rate>${update_rate}</update_rate>
            <pose>0 0 0 0 0 0</pose>
            <visualize>false</visualize>
            <ray>
              <scan>
                <horizontal>
                  <samples>${ray_count}</samples>
                  <resolution>1</resolution>
                  <min_angle>-${field_of_view/2}</min_angle>
                  <max_angle> ${field_of_view/2}</max_angle>
                </horizontal>
                <vertical>
                  <samples>${ray_count}</samples>
                  <resolution>1</resolution>
                  <min_angle>-${field_of_view/2}</min_angle>
                  <max_angle> ${field_of_view/2}</max_angle>
                </vertical>
              </scan>
              <range>
                <min>${min_range}</min>
                <max>${max_range}</max>
                <resolution>0.01</resolution>
              </range>
                <noise>
                    <type>gaussian</type>
                    <!-- Noise parameters based on published spec for Hokuyo laser
                    achieving "+-30mm" accuracy at range < 10m.  A mean of 0.0m and
                    stddev of 0.01m will put 99.7% of samples within 0.03m of the true
                    reading. -->
                    <mean>0.0</mean>
                    <stddev>0.01</stddev>
                </noise>
            </ray>

            <plugin name="gazebo_ros_${name}_controller" filename="libhector_gazebo_ros_sonar.so">
              <gaussianNoise>0.005</gaussianNoise>
              <topicName>${ros_topic}</topicName>
              <frameId>${name}_link</frameId>
            </plugin>
          </sensor>
        </gazebo>
    </xacro:macro>
</robot>